Workbook

Sheet Hoja1
A1: PRODUCTO | B1: DESCRIPCION | C1: UDM | D1: STOCK BODEGA | E1: $ | F1: =SUM(F2:F209) -> 5913475.2 | G1: STOCK RDP | H1: STOCK TOTAL | I1: =SUM(I2:I223) -> 8296133.8
A2: ABARROTES | B2: JAMON SERRANO | C2: KG | D2: 1 | E2: 22060 | F2: =+E2*D2 -> 22060 | G2: =+VLOOKUP(B2,'producto terminado'!B:D,3,) -> 0 | H2: =+G2+D2 -> 1 | I2: =+H2*E2 -> 22060
A3: ABARROTES | B3: HARINA EXTRAFINA 25KG | C3: UN | D3: 2 | E3: 15980 | F3: =+E3*D3 -> 31960 | G3: =+VLOOKUP(B3,'producto terminado'!B:D,3,) -> 0 | H3: =+G3+D3 -> 2 | I3: =+H3*E3 -> 31960
A4: ABARROTES | B4: HARINA PANIFICACION 25KG | C4: UN | D4: 3 | E4: 15850 | F4: =+E4*D4 -> 47550 | G4: =+VLOOKUP(B4,'producto terminado'!B:D,3,) -> 0 | H4: =+G4+D4 -> 3 | I4: =+H4*E4 -> 47550
A5: ABARROTES | B5: SABOR AHUMADO | C5: LT | D5: 0.33 | E5: 12489 | F5: =+E5*D5 -> 4121.37 | G5: =+VLOOKUP(B5,'producto terminado'!B:D,3,) -> 0 | H5: =+G5+D5 -> 0.33 | I5: =+H5*E5 -> 4121.37
A6: ABARROTES | B6: ALCAPARRAS 965G | C6: UN | D6: 2 | E6: 7983 | F6: =+E6*D6 -> 15966 | G6: =+VLOOKUP(B6,'producto terminado'!B:D,3,) -> 0 | H6: =+G6+D6 -> 2 | I6: =+H6*E6 -> 15966
A7: ABARROTES | B7: ACEITUNAS VERDES EN RODAJAS 1,7KG | C7: UN | D7: 1 | E7: 5670 | F7: =+E7*D7 -> 5670 | G7: =+VLOOKUP(B7,'producto terminado'!B:D,3,) -> 0 | H7: =+G7+D7 -> 1 | I7: =+H7*E7 -> 5670
A8: ABARROTES | B8: SALSA INGLESA | C8: LT | D8: 1.5 | E8: 4760 | F8: =+E8*D8 -> 7140 | G8: =+VLOOKUP(B8,'producto terminado'!B:D,3,) -> 0 | H8: =+G8+D8 -> 1.5 | I8: =+H8*E8 -> 7140
A9: ABARROTES | B9: ACETO BALSAMICO | C9: LT | D9: 0 | E9: 4520 | F9: =+E9*D9 -> 0 | G9: =+VLOOKUP(B9,'producto terminado'!B:D,3,) -> 0 | H9: =+G9+D9 -> 0 | I9: =+H9*E9 -> 0
A10: ABARROTES | B10: PALMITOS ENTEROS 810G | C10: UN | D10: 3 | E10: 3780 | F10: =+E10*D10 -> 11340 | G10: =+VLOOKUP(B10,'producto terminado'!B:D,3,) -> 0 | H10: =+G10+D10 -> 3 | I10: =+H10*E10 -> 11340
A11: ABARROTES | B11: ARROZ RISOTTO | C11: KG | D11: 16 | E11: 3600 | F11: =+E11*D11 -> 57600 | G11: =+VLOOKUP(B11,'producto terminado'!B:D,3,) -> 4 | H11: =+G11+D11 -> 20 | I11: =+H11*E11 -> 72000
A12: ABARROTES | B12: PEPINILLOS | C12: KG | D12: 1 | E12: 3450 | F12: =+E12*D12 -> 3450 | G12: =+VLOOKUP(B12,'producto terminado'!B:D,3,) -> 0 | H12: =+G12+D12 -> 1 | I12: =+H12*E12 -> 3450
A13: ABARROTES | B13: MAYO | C13: UN | D13: 1 | E13: 3190 | F13: =+E13*D13 -> 3190 | G13: =+VLOOKUP(B13,'producto terminado'!B:D,3,) -> 0 | H13: =+G13+D13 -> 1 | I13: =+H13*E13 -> 3190
... A27: ABARROTES | B27: COLAPEZ | C27: UN | D27: 112 | E27: 125 | F27: =+E27*D27 -> 14000 | G27: =+VLOOKUP(B27,'producto terminado'!B:D,3,) -> 0 | H27: =+G27+D27 -> 112 | I27: =+H27*E27 -> 14000
A28: ABARROTES | B28: FONDOS DE ALCACHOFAS 950G | C28: UN | D28: 1 | F28: =+E28*D28 -> 0 | G28: =+VLOOKUP(B28,'producto terminado'!B:D,3,) -> 0 | H28: =+G28+D28 -> 1 | I28: =+H28*E28 -> 0
A29: ABARROTES | B29: JUGO DE TOMATE 300CC | C29: UN | D29: 1 | F29: =+E29*D29 -> 0 | G29: =+VLOOKUP(B29,'producto terminado'!B:D,3,) -> 0 | H29: =+G29+D29 -> 1 | I29: =+H29*E29 -> 0
A30: ABARROTES | B30: ACEITUNAS VERDES DESHUESADAS 1,7KG | C30: UN | D30: 1 | F30: =+E30*D30 -> 0 | G30: =+VLOOKUP(B30,'producto terminado'!B:D,3,) -> 0 | H30: =+G30+D30 -> 1 | I30: =+H30*E30 -> 0
A31: ABARROTES | B31: POROTO NEGRO 1KG | C31: UN | D31: 1 | F31: =+E31*D31 -> 0 | G31: =+VLOOKUP(B31,'producto terminado'!B:D,3,) -> 0 | H31: =+G31+D31 -> 1 | I31: =+H31*E31 -> 0
A32: ABARROTES | B32: LEVADURA SECA 125G | C32: UN | D32: 1 | F32: =+E32*D32 -> 0 | G32: =+VLOOKUP(B32,'producto terminado'!B:D,3,) -> 0 | H32: =+G32+D32 -> 1 | I32: =+H32*E32 -> 0
A33: ABARROTES | B33: TROCITOS BARQUILLO | C33: KG | D33: 1 | F33: =+E33*D33 -> 0 | G33: =+VLOOKUP(B33,'producto terminado'!B:D,3,) -> 0 | H33: =+G33+D33 -> 1 | I33: =+H33*E33 -> 0
A34: ABARROTES | B34: MASAS LISTAS FILLO 320G | C34: UN | D34: 0 | F34: =+E34*D34 -> 0 | G34: =+VLOOKUP(B34,'producto terminado'!B:D,3,) -> 0 | H34: =+G34+D34 -> 0 | I34: =+H34*E34 -> 0
A35: ABARROTES | B35: PAN LIBRE DE GLUTEN MOLDE INTEGRAL | C35: UN | D35: 1 | F35: =+E35*D35 -> 0 | G35: =+VLOOKUP(B35,'producto terminado'!B:D,3,) -> 0 | H35: =+G35+D35 -> 1 | I35: =+H35*E35 -> 0
A36: ABARROTES | B36: ENSALADA LISTA | C36: KG | D36: 2.5 | F36: =+E36*D36 -> 0 | G36: =+VLOOKUP(B36,'producto terminado'!B:D,3,) -> 0 | H36: =+G36+D36 -> 2.5 | I36: =+H36*E36 -> 0
A37: ABARROTES | B37: ACEITUNAS NEGRAS EN RODAJAS 1,7KG | C37: UN | D37: 2 | F37: =+E37*D37 -> 0 | G37: =+VLOOKUP(B37,'producto terminado'!B:D,3,) -> 0 | H37: =+G37+D37 -> 2 | I37: =+H37*E37 -> 0
A38: ABARROTES | B38: POROTO PAYAR | C38: KG | D38: 0 | F38: =+E38*D38 -> 0 | G38: =+VLOOKUP(B38,'producto terminado'!B:D,3,) -> 0 | H38: =+G38+D38 -> 0 | I38: =+H38*E38 -> 0
A39: ART DE ASEO | B39: TOALLA DE MANO HOJA SENCILLA 350M | C39: un | D39: 6 | E39: 6578 | F39: =+E39*D39 -> 39468 | G39: =+VLOOKUP(B39,'producto terminado'!B:D,3,) -> 0 | H39: =+G39+D39 -> 6 | I39: =+H39*E39 -> 39468
A40: ART DE ASEO | B40: GUANTES BLACK L 100pcs | C40: cj | D40: 4 | E40: 4650 | F40: =+E40*D40 -> 18600 | G40: =+VLOOKUP(B40,'producto terminado'!B:D,3,) -> 0 | H40: =+G40+D40 -> 4 | I40: =+H40*E40 -> 18600
A41: ART DE ASEO | B41: GUANTES BLACK S 100pcs | C41: cj | D41: 2 | E41: 4650 | F41: =+E41*D41 -> 9300 | G41: =+VLOOKUP(B41,'producto terminado'!B:D,3,) -> 0 | H41: =+G41+D41 -> 2 | I41: =+H41*E41 -> 9300
A42: ART DE ASEO | B42: PAPEL HIGENICO ROLLO JUMBO 400M | C42: un | D42: 5 | E42: 2035 | F42: =+E42*D42 -> 10175 | G42: =+VLOOKUP(B42,'producto terminado'!B:D,3,) -> 0 | H42: =+G42+D42 -> 5 | I42: =+H42*E42 -> 10175
A43: ART DE ASEO | B43: PAÑO MULTIUSO TRADICIONAL | C43: PACK | D43: 6 | E43: 1640 | F43: =+E43*D43 -> 9840 | G43: =+VLOOKUP(B43,'producto terminado'!B:D,3,) -> 0 | H43: =+G43+D43 -> 6 | I43: =+H43*E43 -> 9840
A44: ART DE ASEO | B44: TRAPERO DOBLE c/OJAL 50x50 | C44: un | D44: 1 | E44: 1470 | F44: =+E44*D44 -> 1470 | G44: =+VLOOKUP(B44,'producto terminado'!B:D,3,) -> 0 | H44: =+G44+D44 -> 1 | I44: =+H44*E44 -> 1470
A45: ART DE ASEO | B45: DESODORANTE AMBIENTAL | C45: un | D45: 1 | E45: 1190 | F45: =+E45*D45 -> 1190 | G45: =+VLOOKUP(B45,'producto terminado'!B:D,3,) -> 0 | H45: =+G45+D45 -> 1 | I45: =+H45*E45 -> 1190
A46: ART DE ASEO | B46: TRAPERO 50x50 c/OJAL | C46: un | D46: 1 | E46: 1030 | F46: =+E46*D46 -> 1030 | G46: =+VLOOKUP(B46,'producto terminado'!B:D,3,) -> 0 | H46: =+G46+D46 -> 1 | I46: =+H46*E46 -> 1030
A47: ART DE ASEO | B47: PASTILLA LIMPIADORA HORNO VERDE | C47: un | D47: 100 | E47: 940 | F47: =+E47*D47 -> 94000 | G47: =+VLOOKUP(B47,'producto terminado'!B:D,3,) -> 0 | H47: =+G47+D47 -> 100 | I47: =+H47*E47 -> 94000
A48: ART DE ASEO | B48: ESPONJA DE ACERO EXTRA GRANDE | C48: un | D48: 13 | E48: 930 | F48: =+E48*D48 -> 12090 | G48: =+VLOOKUP(B48,'producto terminado'!B:D,3,) -> 0 | H48: =+G48+D48 -> 13 | I48: =+H48*E48 -> 12090
A49: ART DE ASEO | B49: PASTILLA LIMPIADORA HORNO AZUL | C49: un | D49: 100 | E49: 766 | F49: =+E49*D49 -> 76600 | G49: =+VLOOKUP(B49,'producto terminado'!B:D,3,) -> 0 | H49: =+G49+D49 -> 100 | I49: =+H49*E49 -> 76600
A50: ART DE ASEO | B50: ESPONJA FIBRA | C50: un | D50: 148 | E50: 230 | F50: =+E50*D50 -> 34040 | G50: =+VLOOKUP(B50,'producto terminado'!B:D,3,) -> 0 | H50: =+G50+D50 -> 148 | I50: =+H50*E50 -> 34040
... A54: ART DE ASEO | B54: LADRILLO PARA PARRILLA | C54: un | D54: 9 | E54: 4909 | F54: =+E54*D54 -> 44181 | G54: =+VLOOKUP(B54,'producto terminado'!B:D,3,) -> 0 | H54: =+G54+D54 -> 9 | I54: =+H54*E54 -> 44181
A55: ART DE ASEO | B55: ESCOBILLA LAVAROPA | C55: un | D55: 1 | F55: =+E55*D55 -> 0 | G55: =+VLOOKUP(B55,'producto terminado'!B:D,3,) -> 0 | H55: =+G55+D55 -> 1 | I55: =+H55*E55 -> 0
A56: ART DE ASEO | B56: LIMPIADOR DE PISO 5LT | C56: un | D56: 4 | F56: =+E56*D56 -> 0 | G56: =+VLOOKUP(B56,'producto terminado'!B:D,3,) -> 0 | H56: =+G56+D56 -> 4 | I56: =+H56*E56 -> 0
...

Sheet producto terminado
A1: PRODUCTO | B1: DESCRIPCION | C1: UDM | D1: STOCK | E1: $ | F1: =SUM(F2:F209) -> 1411104.2
A2: HELADO | B2: FRUTILLA | C2: UN | D2: 0.25 | E2: 21900 | F2: =+E2*D2 -> 5475
A3: LACTEOS | B3: MANTEQUILLA SIN SAL 5KG | C3: UN | D3: 0.4 | E3: 40000 | F3: =+E3*D3 -> 16000
A4: HELADO | B4: FRAMBUESA | C4: UN | D4: 0.5 | E4: 21900 | F4: =+E4*D4 -> 10950
A5: PROTEINA | B5: POLLO ARVERJADO | C5: KG | D5: 0.5 | E5: 2790 | F5: =+E5*D5 -> 1395
A6: HELADO | B6: PISTACHO | C6: UN | D6: 0.5 | F6: =+E6*D6 -> 0
A7: VERDURA | B7: MIX DE HOJA | C7: KG | D7: 0.6 | E7: 7000 | F7: =+E7*D7 -> 4200
A8: PROTEINA | B8: COSTILLAR | C8: KG | D8: 0.9 | E8: 6444 | F8: =+E8*D8 -> 5799.6
A9: HELADO | B9: CHOCOLATE | C9: UN | D9: 0.9 | E9: 23900 | F9: =+E9*D9 -> 21510
A10: CAFETERIA | B10: LUCAFFE CAPSULA ESPRESSO | C10: UN | D10: 1 | E10: =550*150 -> 82500 | F10: =+E10*D10 -> 82500
A11: HELADO | B11: VAINILLA | C11: UN | D11: 1.2 | E11: 21900 | F11: =+E11*D11 -> 26280
A12: LACTEOS | B12: QUESO PARMESANO | C12: KG | D12: 1.49 | E12: 9990 | F12: =+E12*D12 -> 14885.1
A13: LACTEOS | B13: LECHE ENTERA LIQUIDA 1LT | C13: UN | D13: 2 | E13: 1400 | F13: =+E13*D13 -> 2800
A14: CONGELADOS | B14: PULPA MANGO M | C14: KG | D14: 2 | E14: 2700 | F14: =+E14*D14 -> 5400
A15: CAFETERIA | B15: TE MANZANILLA | C15: UN | D15: 2 | E15: 325 | F15: =+E15*D15 -> 650
A16: FRUTA | B16: PIÑA | C16: UN | D16: 2 | E16: 3500 | F16: =+E16*D16 -> 7000
A17: INSUMOS | B17: SERVILLETAS RESTAURANTE 160UN | C17: UN | D17: 2 | F17: =+E17*D17 -> 0
A18: BEBIDAS | B18: SPRITE 1,5 | C18: UN | D18: 2 | F18: =+E18*D18 -> 0
A19: PROTEINA | B19: CAMARON NAILON | C19: KG | D19: 2.35 | E19: 14300 | F19: =+E19*D19 -> 33605
A20: PROTEINA | B20: MALAYA | C20: KG | D20: =0.3*8 -> 2.4 | F20: =+E20*D20 -> 0
A21: PROTEINA | B21: SALMON FRESCO | C21: KG | D21: =12*0.2 -> 2.4 | E21: 13390 | F21: =+E21*D21 -> 32136
A22: CAFETERIA | B22: AZUCAR BLANCA GRANULADA 1KG | C22: UN | D22: 2.5 | E22: 1154 | F22: =+E22*D22 -> 2885
A23: PROTEINA | B23: MERLUSA AUSTRAL | C23: UN | D23: =17*0.2 -> 3.4 | E23: 11790 | F23: =+E23*D23 -> 40086
A24: CONDIMENTOS | B24: SAL DE MESA 1KG | C24: UN | D24: 3.5 | E24: 495 | F24: =+E24*D24 -> 1732.5
A25: PROTEINA | B25: PULPO | C25: KG | D25: 3.91 | E25: 12400 | F25: =+E25*D25 -> 48484
A26: CONGELADOS | B26: PULPA PIÑA | C26: KG | D26: 4 | E26: 5800 | F26: =+E26*D26 -> 23200
A27: ABARROTES | B27: ARROZ RISOTTO | C27: KG | D27: 4 | E27: 3600 | F27: =+E27*D27 -> 14400
A28: VERDURA | B28: LIMON AMARILLO | C28: KG | D28: 4 | E28: 639 | F28: =+E28*D28 -> 2556
A29: PROTEINA | B29: OSOBUCO | C29: KG | D29: =0.5*9 -> 4.5 | E29: 10990 | F29: =+E29*D29 -> 49455
A30: PROTEINA | B30: OSTION | C30: KG | D30: 4.675 | E30: 26950 | F30: =+E30*D30 -> 125991.25
A31: VERDURA | B31: LECHUGA LOLLO VERDE | C31: UN | D31: 5 | E31: 500 | F31: =+E31*D31 -> 2500
A32: BEBIDAS | B32: TONICA LATA | C32: UN | D32: 5 | F32: =+E32*D32 -> 0
A33: PROTEINA | B33: LOMO VETADO | C33: KG | D33: 5.265 | E33: 25490 | F33: =+E33*D33 -> 134204.85
A34: CONGELADOS | B34: PULPA MANGO | C34: KG | D34: 6 | E34: 6500 | F34: =+E34*D34 -> 39000
A35: CONGELADOS | B35: PULPA FRUTILLA | C35: KG | D35: 6 | E35: 4800 | F35: =+E35*D35 -> 28800
A36: PROTEINA | B36: SALSA DE OSTION | C36: KG | D36: 6.655 | F36: =+E36*D36 -> 0
A37: HIERBA | B37: MENTA | C37: KG | D37: 7 | E37: 8500 | F37: =+E37*D37 -> 59500
A38: PROTEINA | B38: ATUN | C38: KG | D38: 7.185 | E38: 11990 | F38: =+E38*D38 -> 86148.15
A39: PASTA | B39: FETUCCINI | C39: KG | D39: 9.554 | E39: 9500 | F39: =+E39*D39 -> 90763
A40: BEBIDAS | B40: COCA COLA | C40: UN | D40: 10 | F40: =+E40*D40 -> 0
...
